<mujoco model="locobot">
    <compiler angle="radian" meshdir="../stls/locobot" />
    <size njmax="500" nconmax="100" />
    <asset>
        <mesh name="plate_bottom" file="plate_bottom.STL" scale="0.001 0.001 0.001" />
        <mesh name="plate_top" file="plate_top.STL" scale="0.001 0.001 0.001" />
        <mesh name="battery" file="battery.STL" scale="0.001 0.001 0.001" />
        <mesh name="mobile_base" file="mobile_base.STL" scale="0.001 0.001 0.001" />
        <mesh name="shoulder_link" file="shoulder_link.STL" />
        <mesh name="elbow_link" file="elbow_link.STL" />
        <mesh name="forearm_link" file="forearm_link.STL" />
        <mesh name="wrist_link" file="wrist_link.STL" />
        <mesh name="gripper_link" file="gripper_link.STL" />
        <mesh name="finger_r" file="finger_r.STL" />
        <mesh name="finger_l" file="finger_l.STL" />
        <mesh name="ar_tag" file="ar_tag.STL" />
    </asset>
    <worldbody>
        <!-- robot view -->
        <camera fovy="43.3" name="main_cam" pos="0.81822263 -0.05511966  0.45810006" quat="-0.3351224   0.6429879   0.61176364 -0.31623533" ></camera>
        <site rgba="1 0 0 1" name="main_cam_site" pos="0.81822263 -0.05511966  0.45810006" quat="-0.3351224   0.6429879   0.61176364 -0.31623533" type="box" size="0.02 0.05 0.1"></site>
        <site rgba="1 0 0 1" name="origin_site" pos="0 0 0" quat="1 0 0 0" size="0.02"></site>

        <geom size="0.178 0.05469" pos="0 0 0.06969" type="cylinder" />
        <geom size="0.017 0.0088" pos="0.115 0 0.0172" quat="0.707107 -0.707107 0 0" type="cylinder" />
        <geom size="0.017 0.0088" pos="-0.135 0 0.0192" quat="0.707107 -0.707107 0 0" type="cylinder" />
        <geom pos="0 0 0.102813" quat="0 0.707107 0.707107 0" type="mesh" rgba="0.792157 0.819608 0.933333 1" mesh="plate_bottom" />
        <geom pos="0 0 0.107563" quat="0 0.707107 0.707107 0" type="mesh" rgba="0.792157 0.819608 0.933333 1" mesh="plate_top" />
        <geom pos="0.00026679 -0.0217673 0.110563" quat="0.707107 0 0 0.707107" type="mesh" mesh="battery" />
        <geom pos="0.001527 0 0.00191227" quat="0.5 0.5 0.5 0.5" type="mesh" rgba="0.792157 0.819608 0.933333 1" mesh="mobile_base" />
        <!-- <body name="wheel_left_link" pos="0 0.115 0.0352" quat="0.707107 -0.707107 0 0">
            <inertial pos="0 0 0" mass="0.01" diaginertia="0.001 0.001 0.001" />
            <joint name="wheel_left_joint" pos="0 0 0" axis="0 0 1" />
            <geom size="0.0352 0.0103" type="cylinder" />
        </body>
        <body name="wheel_right_link" pos="0 -0.115 0.0352" quat="0.707107 -0.707107 0 0">
            <inertial pos="0 0 0" mass="0.01" diaginertia="0.001 0.001 0.001" />
            <joint name="wheel_right_joint" pos="0 0 0" axis="0 0 1" />
            <geom size="0.035 0.0103" type="cylinder" />
        </body> -->
        <body name="shoulder_link" pos="0.0973 0 0.173063">
            <inertial pos="-5.67969e-05 1.09785e-10 0.0228467" quat="0.70709 0.70709 0.00489782 -0.00489782" mass="0.119861" diaginertia="0.00016129 0.000150799 5.49697e-05" />
            <joint name="joint_1" pos="0 0 0" axis="0 0 1" limited="true" range="-1.57 1.57" />
            <!-- TODO: add names -->
            <geom type="mesh" rgba="0.792157 0.819608 0.933333 1" mesh="shoulder_link" />
            <body name="elbow_link" pos="0 0 0.04125">
                <inertial pos="0.00959756 -2.3093e-10 0.134297" quat="0.705844 0.0422381 0.0422381 0.705844" mass="0.212483" diaginertia="0.0012235 0.00119077 7.43429e-05" />
                <joint name="joint_2" pos="0 0 0" axis="0 1 0" limited="true" range="-1.57 1.57" />
                <geom type="mesh" rgba="0.792157 0.819608 0.933333 1" mesh="elbow_link" />
                <body name="forearm_link" pos="0.05 0 0.2">
                    <inertial pos="0.11783 0 -1.26219e-08" quat="0 0.707107 0 0.707107" mass="0.187464" diaginertia="0.000737166 0.00072521 3.94143e-05" />
                    <joint name="joint_3" pos="0 0 0" axis="0 1 0" limited="true" range="-1.57 1.57" />
                    <geom type="mesh" rgba="0.792157 0.819608 0.933333 1" mesh="forearm_link" />
                    <body name="wrist_link" pos="0.2002 0 0">
                        <inertial pos="0.042941 4.98645e-05 0.0114267" quat="0.0526331 0.462852 0.0284284 0.884415" mass="0.0605922" diaginertia="2.0979e-05 2.08943e-05 1.73078e-05" />
                        <joint name="joint_4" pos="0 0 0" axis="0 1 0" limited="true" range="-1.57 1.57" />
                        <geom type="mesh" rgba="0.792157 0.819608 0.933333 1" mesh="wrist_link" />
                        <body name="gripper_link" pos="0.063 0.0001 0">
                            <inertial pos="0.0303034 -1.00406e-05 0.0150805" quat="0.359874 0.610879 0.606151 0.360414" mass="0.0998368" diaginertia="6.24793e-05 6.16818e-05 4.76112e-05" />
                            <joint name="joint_5" pos="0 0 0" axis="-1 0 0" limited="true" range="-1.57 1.57" />
                            <geom type="mesh" rgba="0.792157 0.819608 0.933333 1" mesh="gripper_link" />
                            <geom name="ar_tag_geom" pos="0.02695 0 0.04315" type="mesh" rgba="0.792157 0.819608 0.933333 1" mesh="ar_tag" />
                            <body name="finger_r" pos="0.07285 0 0.0050143">
                                <inertial pos="0.0100191 -0.00843835 -0.0048328" quat="0.475246 0.475678 0.523898 0.522879" mass="0.0121931" diaginertia="3.13241e-06 2.77936e-06 6.51268e-07" />
                                <joint name="joint_6" pos="0 0 0" axis="0 1 0" type="slide" limited="true" range="-1 0" />
                                <geom type="mesh" rgba="0.792157 0.819608 0.933333 1" mesh="finger_r" />
                            </body>
                            <body name="finger_l" pos="0.07285 0 0.0050143">
                                <inertial pos="0.0100192 0.00643833 -0.0048328" quat="0.522879 0.523899 0.475677 0.475246" mass="0.0121931" diaginertia="3.13241e-06 2.77936e-06 6.51268e-07" />
                                <joint name="joint_7" pos="0 0 0" axis="0 1 0" type="slide" limited="true" range="0 1" />
                                <geom type="mesh" rgba="0.792157 0.819608 0.933333 1" mesh="finger_l" />
                            </body>
                        </body>
                    </body>
                </body>
            </body>
        </body>
    </worldbody>
</mujoco>
