<mujoco model="widowx_arm">
    <compiler angle="radian" meshdir="../stls/widowx" />
    <size njmax="500" nconmax="100" />
    <asset>
        <texture type="skybox" builtin="gradient" rgb1="0.2 0.2 0.2" rgb2="0.46 0.87 0.58" width="32" height="32"></texture>
        <mesh name="base_link" file="base_link.stl" />
        <mesh name="shoulder_link" file="shoulder_link.stl" scale="1.3 1.3 1.3"/>
        <mesh name="biceps_link" file="biceps_link.stl" scale="1.3 1.3 1.3" />
        <mesh name="forearm_link" file="forearm_link.stl" scale="1.3 1.3 1.3" />
        <mesh name="wrist_1_link" file="wrist_1_link.stl" scale="1.3 1.3 1.3" />
        <mesh name="wrist_2_link" file="wrist_2_link.stl" scale="1.3 1.3 1.3" />
        <mesh name="gripper_rail_link" file="gripper_rail_link.stl" scale="1.3 1.3 1.3"/>
        <mesh name="gripper_hand_fixed_link" file="gripper_hand_fixed_link.stl" scale="1.3 1.3 1"/>
    </asset>
    <worldbody>
      <body name="base" pos = "0 0 0" >
       <body name="eef_body">
          <site rgba="1 1 0 1" pos="0 0 0" size="0.01"  name="eef_pos"></site>
        </body>
        	<!-- robot view -->
			<camera fovy="43.3" name="main_cam" pos="1.17201246 0.35119113 0.31265177" quat="0.63589577  0.64909113 -0.28874116 -0.30157226" ></camera>
			<site rgba="1 0 0 1" name="main_cam_site" pos="1.17201246 0.35119113 0.31265177" quat="0.63589577  0.64909113 -0.28874116 -0.30157226" type="box" size="0.02 0.05 0.1"></site>
        <geom size="0.0005 0.0005 0.0005" type="box" contype="0" conaffinity="0" group="1" />
        <geom name="base_link_mesh" type="mesh" contype="0" conaffinity="0" group="1" rgba="0.15 0.15 0.15 1" mesh="base_link" />
        <!-- <geom type="mesh" rgba="0.15 0.15 0.15 1" mesh="base_link" /> -->
        <body name="shoulder_link" pos="0 0 0.125">
            <inertial pos="0 0 0" mass="1" diaginertia="1 1 1" />
            <joint name="joint_1" pos="0 0 0" axis="0 0 1" limited="true" range="-2.617 2.617" />
            <geom name="shoulder_link_mesh" type="mesh" contype="0" conaffinity="0" group="1" rgba="0.15 0.15 0.15 1" mesh="shoulder_link" />
            <!-- <geom type="mesh" rgba="0.15 0.15 0.15 1" mesh="shoulder_link" /> -->
            <body name="biceps_link" pos="0 0 0">
                <inertial pos="0 0 0" mass="1" diaginertia="1 1 1" />
                <joint name="joint_2" pos="0 0 0" axis="0 1 0" limited="true" range="-1.571 1.571" />
                <geom name="biceps_link_mesh" pos="0.04825 0 0.14" type="mesh" contype="0" conaffinity="0" group="1" rgba="0.15 0.15 0.15 1" mesh="biceps_link" />
                <!-- <geom type="mesh" rgba="0.15 0.15 0.15 1" mesh="biceps_link" /> -->
                <body name="forearm_link" pos="0.04825 0 0.14203" quat="0.707107 0 0.707106 0">
                    <inertial pos="0 0 0" mass="1" diaginertia="1 1 1" />
                    <joint name="joint_3" pos="0 0 0" axis="0 1 0" limited="true" range="-1.571 1.571" />
                    <geom name="forearm_link_mesh" pos="0 0 0.14203" type="mesh" contype="0" conaffinity="0" group="1" rgba="0.15 0.15 0.15 1" mesh="forearm_link" />
                    <!-- <geom type="mesh" rgba="0.15 0.15 0.15 1" mesh="forearm_link" /> -->
                    <body name="wrist_1_link" pos="0 0 0.14203">
                        <inertial pos="0 0 0" mass="1" diaginertia="1 1 1" />
                        <joint name="joint_4" pos="0 0 0" axis="0 1 0" limited="true" range="-1.745 1.745" />
                        <geom name="wrist_1_link_mesh" type="mesh" contype="0" conaffinity="0" group="1" rgba="0.15 0.15 0.15 1" mesh="wrist_1_link" />
                        <!-- <geom type="mesh" rgba="0.15 0.15 0.15 1" mesh="wrist_1_link" /> -->
                        <body name="wrist_2_link" pos="0 0 0.0715">
                            <inertial pos="0 0 0.0215" mass="2" diaginertia="2.00092 2.00092 2" />
                            <joint name="joint_5" pos="0 0 0" axis="0 0 1" limited="true" range="-2.617 2.617" />
                            <geom name="wrist_2_link_mesh" pos="0 0 0.043" type="mesh" contype="0" conaffinity="0" group="1" rgba="0.15 0.15 0.15 1" mesh="wrist_2_link" />
                            <!-- <geom type="mesh" rgba="0.15 0.15 0.15 1" mesh="wrist_2_link" /> -->
                            <geom name="gripper_rail_link_mesh" pos="0 0 0.043" quat="0.707388 0 0 0.706825" type="mesh" contype="0" conaffinity="0" group="1" rgba="0.15 0.15 0.15 1" mesh="gripper_rail_link" />
                            <!-- <geom pos="0 0 0.043" type="mesh" rgba="0.15 0.15 0.15 1" mesh="gripper_rail_link" /> -->
                            <body name="gripper_aux_link" pos="0 0 0.043">
                                <inertial pos="0 0 0" mass="1" diaginertia="1 1 1" />
                                <joint name="gripper_revolute_joint" pos="0 0 0" axis="0 0 1" limited="true" range="0 2.6" />
                            </body>
                            <!-- <body name="gripper_1_link" pos="0 0 0.043">
                                <inertial pos="0 0 0" mass="1" diaginertia="1 1 1" />
                                <joint name="gripper_prismatic_joint_1" pos="0 0 0" axis="0 -1 0" type="slide" limited="true" range="0 0.027" />
                                <geom name="gripper_hand_fixed_link_mesh_1" pos="0 -0.0007 0" quat="0.707388 0 0 0.706825" type="mesh" contype="0" conaffinity="0" group="1" rgba="0.15 0.15 0.15 1" mesh="gripper_hand_fixed_link" />
                                <geom type="mesh" rgba="0.15 0.15 0.15 1" mesh="gripper_hand_fixed_link" />
                            </body>
                            <body name="gripper_2_link" pos="0 0 0.043">
                                <inertial pos="0 0 0" mass="1" diaginertia="1 1 1" />
                                <joint name="gripper_prismatic_joint_2" pos="0 0 0" axis="0 1 0" type="slide" limited="true" range="0 0.027" />
                                <geom name="gripper_hand_fixed_link_mesh_2"  pos="0 0.0007 0" quat="0.707388 0 0 -0.706825" type="mesh" contype="0" conaffinity="0" group="1" rgba="0.15 0.15 0.15 1" mesh="gripper_hand_fixed_link" />
                                <geom type="mesh" rgba="0.15 0.15 0.15 1" mesh="gripper_hand_fixed_link" />
                            </body> -->
                        </body>
                    </body>
                </body>
            </body>
        </body>
      </body>
    </worldbody>
</mujoco>
